<mujoco model="walker_tienkung_ei">
  <compiler angle="radian" meshdir="../meshes/walker_tienkung_ei" autolimits="true"/>
  <option timestep="0.002" iterations='10' solver='PGS' gravity='0 0 -9.81' apirate='1000'>
  </option>
  <size njmax="500" nconmax="100" />
  <default>
    <geom  condim='4' solref='0.001 2' friction='1.0 0.5 0.5'/>
    <equality solref='0.001 2'/>
  </default>
  <visual>
      <quality shadowsize='4096'/>
      <map force="0.1" zfar="30" znear='0.05'/>
      <rgba haze="0.15 0.25 0.35 1"/>
      <global offwidth="2560" offheight="1440" elevation="-20" azimuth="120"/>
  </visual>
  <default>
    <default class="walker_tienkung_ei">
      <joint damping="1" armature="0.1"/>
      <default class="visual">
        <geom type="mesh" contype="0" conaffinity="0" group="2" />
      </default>
      <default class="collision">
        <geom group="3" mass="0" density="0" friction="1.0 0.5 0.5" />
      </default>
    </default>
  </default>

  <asset>
    <texture type="skybox" builtin="gradient" rgb1=".3 .5 .7" rgb2="0 0 0" width="32" height="512"/>
    <texture name="body" type="cube" builtin="flat" mark="cross" width="128" height="128" rgb1="0.8 0.6 0.4" rgb2="0.8 0.6 0.4" markrgb="1 1 1" random="0.01"/>
    <material name="body" texture="body" texuniform="true" rgba="0.8 0.6 .4 1"/>
    <texture name="grid" type="2d" builtin="checker" width="512" height="512" rgb1=".1 .2 .3" rgb2=".2 .3 .4"/>
    <material name="grid" texture="grid" texrepeat="1 1" texuniform="true" reflectance="0.02"/>
  </asset>
  <asset>
    <mesh name="pelvis" file="pelvis.STL"/>
    <mesh name="hip_roll_l_link" file="hip_roll_l_link.STL"/>
    <mesh name="hip_pitch_l_link" file="hip_pitch_l_link.STL"/>
    <mesh name="hip_yaw_l_link" file="hip_yaw_l_link.STL"/>
    <mesh name="knee_pitch_l_link" file="knee_pitch_l_link.STL"/>
    <mesh name="ankle_pitch_l_link" file="ankle_pitch_l_link.STL"/>
    <mesh name="ankle_roll_l_link" file="ankle_roll_l_link.STL"/>
    <mesh name="hip_roll_r_link" file="hip_roll_r_link.STL"/>
    <mesh name="hip_pitch_r_link" file="hip_pitch_r_link.STL"/>
    <mesh name="hip_yaw_r_link" file="hip_yaw_r_link.STL"/>
    <mesh name="knee_pitch_r_link" file="knee_pitch_r_link.STL"/>
    <mesh name="ankle_pitch_r_link" file="ankle_pitch_r_link.STL"/>
    <mesh name="ankle_roll_r_link" file="ankle_roll_r_link.STL"/>
    <mesh name="waist_yaw_link" file="waist_yaw_link.STL"/>
    <mesh name="head_yaw_link" file="head_yaw_link.STL"/>
    <mesh name="head_pitch_link" file="head_pitch_link.STL"/>
    <mesh name="head_roll_link" file="head_roll_link.STL"/>
    <mesh name="camera_head_link" file="camera_head_link.STL"/>
    <mesh name="shoulder_pitch_l_link" file="shoulder_pitch_l_link.STL"/>
    <mesh name="shoulder_roll_l_link" file="shoulder_roll_l_link.STL"/>
    <mesh name="shoulder_yaw_l_link" file="shoulder_yaw_l_link.STL"/>
    <mesh name="elbow_pitch_l_link" file="elbow_pitch_l_link.STL"/>
    <mesh name="elbow_yaw_l_link" file="elbow_yaw_l_link.STL"/>
    <mesh name="wrist_pitch_l_link" file="wrist_pitch_l_link.STL"/>
    <mesh name="wrist_roll_l_link" file="wrist_roll_l_link.STL"/>
    <mesh name="shoulder_pitch_r_link" file="shoulder_pitch_r_link.STL"/>
    <mesh name="shoulder_roll_r_link" file="shoulder_roll_r_link.STL"/>
    <mesh name="shoulder_yaw_r_link" file="shoulder_yaw_r_link.STL"/>
    <mesh name="elbow_pitch_r_link" file="elbow_pitch_r_link.STL"/>
    <mesh name="elbow_yaw_r_link" file="elbow_yaw_r_link.STL"/>
    <mesh name="wrist_pitch_r_link" file="wrist_pitch_r_link.STL"/>
    <mesh name="wrist_roll_r_link" file="wrist_roll_r_link.STL"/>
    <mesh name="camera_body_front_link" file="camera_body_front_link.STL"/>
    <mesh name="camera_body_back_link" file="camera_body_back_link.STL"/>
  </asset>

  <worldbody>
  <geom name="floor" pos="0 0 0" size="50 50 .05" type="plane" material="grid" condim="3"/>
  <light directional="true" diffuse=".8 .8 .8" specular=".2 .2 .2" pos="0 0 5" dir="0 0 -1"/>
  <body name="pelvis" pos="0 0.0 1.1" euler="0 0 1.5708" childclass="walker_tienkung_ei">
    <inertial pos="0.00029935 -1.8119e-07 0.023406" quat="0.999999 0.000213974 0.00165245 0.00039263" mass="3.5" diaginertia="0.01330575 0.01205119 0.00625631"/>
    <joint name="floating_base_joint" type="free" limited="false" actuatorfrclimited="false"/>
    <geom type="mesh" class="visual" contype="0" conaffinity="0" group="1" density="0" rgba="0.752941 0.752941 0.752941 1" mesh="pelvis"/>
    <geom type="sphere" size="0.07" pos="0.00259459 0 0.00656728" rgba="0.86667 0.86667 0.8902 1"/>
    <site name="imu_site" size="0.01" pos="0 0 0" rgba="1 0 0 1"/>
    <body name="hip_roll_l_link" pos="0 0.028 -0.0857">
      <inertial pos="-0.001848 0.055849 -0.036017" quat="-0.248001 0.650774 -0.26447 0.667116" mass="0.672983" diaginertia="0.00353091 0.00296469 0.0010174"/>
      <joint name="hip_roll_l_joint" pos="0 0 0" axis="1 0 0" range="-0.79 0.79" actuatorfrcrange="-160 160"/>
      <geom type="mesh" class="visual" rgba="0.752941 0.752941 0.752941 1" mesh="hip_roll_l_link"/>
      <body name="hip_pitch_l_link" pos="0 0.122 -0.046">
        <inertial pos="0.001125 0.001644 -0.01177" quat="0.705651 0.0579324 0.0569728 0.703885" mass="4.22793" diaginertia="0.0251351 0.0168268 0.0152311"/>
        <joint name="hip_pitch_l_joint" pos="0 0 0" axis="0 1 0" range="-2.79 2.09" actuatorfrcrange="-300 300"/>
        <geom type="mesh" class="visual" rgba="0.752941 0.752941 0.752941 1" mesh="hip_pitch_l_link"/>
        <body name="hip_yaw_l_link" pos="0 0 -0.0987">
          <inertial pos="0.004124 -0.006494 -0.119737" quat="0.714037 0.00934045 -0.00790408 0.700001" mass="6.5727" diaginertia="0.063314 0.0560402 0.0210828"/>
          <joint name="hip_yaw_l_joint" pos="0 0 0" axis="0 0 1" range="-1.04 1.04" actuatorfrcrange="-160 160"/>
          <geom type="mesh" class="visual" rgba="0.752941 0.752941 0.752941 1" mesh="hip_yaw_l_link"/>
          <body name="knee_pitch_l_link" pos="0 -4.2833e-05 -0.3013">
            <inertial pos="0.007489 0.001584 -0.167773" quat="0.746572 -0.012866 -0.0247827 0.664718" mass="3.01799" diaginertia="0.0362398 0.0356959 0.00184529"/>
            <joint name="knee_pitch_l_joint" pos="0 0 0" axis="0 1 0" range="0 2.39" actuatorfrcrange="-300 300"/>
            <geom type="mesh" class="visual" rgba="0.752941 0.752941 0.752941 1" mesh="knee_pitch_l_link"/>
            <body name="ankle_pitch_l_link" pos="0 0 -0.4">
              <inertial pos="1.23077e-09 5.88533e-10 0" quat="0.5 0.5 -0.5 0.5" mass="0.111609" diaginertia="3.2e-05 1.8e-05 1.8e-05"/>
              <joint name="ankle_pitch_l_joint" pos="0 0 0" axis="0 1 0" range="-1.22 0.5236" actuatorfrcrange="-60 60"/>
              <geom type="mesh" class="visual" rgba="0.752941 0.752941 0.752941 1" mesh="ankle_pitch_l_link"/>
              <body name="ankle_roll_l_link" pos="0 0 0">
                <inertial pos="0.021235 -4.62707e-08 -0.032883" quat="-4.10884e-06 0.6645 -9.6485e-06 0.747289" mass="1.01738" diaginertia="0.0063132 0.006055 0.000954799"/>
                <joint name="ankle_roll_l_joint" pos="0 0 0" axis="1 0 0" range="-0.4363 0.4363" actuatorfrcrange="-30 30"/>
                <geom type="mesh" class="visual" rgba="0.752941 0.752941 0.752941 1" mesh="ankle_roll_l_link"/>
              </body>
            </body>
          </body>
        </body>
      </body>
    </body>
    <body name="hip_roll_r_link" pos="0 -0.028 -0.0857">
      <inertial pos="-0.001848 -0.055849 -0.036017" quat="0.248001 0.650774 0.26447 0.667116" mass="0.672983" diaginertia="0.00353091 0.00296469 0.0010174"/>
      <joint name="hip_roll_r_joint" pos="0 0 0" axis="1 0 0" range="-0.79 0.79" actuatorfrcrange="-160 160"/>
      <geom type="mesh" class="visual" rgba="0.752941 0.752941 0.752941 1" mesh="hip_roll_r_link"/>
      <body name="hip_pitch_r_link" pos="0 -0.122 -0.046">
        <inertial pos="0.001125 -0.001644 -0.01177" quat="0.703885 0.0569728 0.0579324 0.705651" mass="4.22793" diaginertia="0.0251351 0.0168268 0.0152311"/>
        <joint name="hip_pitch_r_joint" pos="0 0 0" axis="0 1 0" range="-2.79 2.09" actuatorfrcrange="-300 300"/>
        <geom type="mesh" class="visual" rgba="0.752941 0.752941 0.752941 1" mesh="hip_pitch_r_link"/>
        <body name="hip_yaw_r_link" pos="0 0 -0.0987">
          <inertial pos="0.00374 0.005658 -0.117755" quat="0.702011 -0.0106516 0.0134004 0.711961" mass="7.1829" diaginertia="0.0648981 0.057772 0.0228178"/>
          <joint name="hip_yaw_r_joint" pos="0 0 0" axis="0 0 1" range="-1.04 1.04" actuatorfrcrange="-160 160"/>
          <geom type="mesh" class="visual" rgba="0.752941 0.752941 0.752941 1" mesh="hip_yaw_r_link"/>
          <body name="knee_pitch_r_link" pos="0 0.00015001 -0.3013">
            <inertial pos="0.007489 -0.001584 -0.167773" quat="0.664718 -0.0247827 -0.012866 0.746572" mass="3.01799" diaginertia="0.0362398 0.0356959 0.00184529"/>
            <joint name="knee_pitch_r_joint" pos="0 0 0" axis="0 1 0" range="0 2.39" actuatorfrcrange="-300 300"/>
            <geom type="mesh" class="visual" rgba="0.752941 0.752941 0.752941 1" mesh="knee_pitch_r_link"/>
            <body name="ankle_pitch_r_link" pos="0 0.00074981 -0.4">
              <inertial pos="1.23077e-09 -5.88533e-10 0" quat="0.5 0.5 -0.5 0.5" mass="0.111609" diaginertia="3.2e-05 1.8e-05 1.8e-05"/>
              <joint name="ankle_pitch_r_joint" pos="0 0 0" axis="0 1 0" range="-1.22 0.5236" actuatorfrcrange="-60 60"/>
              <geom type="mesh" class="visual" rgba="0.752941 0.752941 0.752941 1" mesh="ankle_pitch_r_link"/>
              <body name="ankle_roll_r_link" pos="0 0 0">
                <inertial pos="0.021235 4.62707e-08 -0.032883" quat="4.10884e-06 0.6645 9.6485e-06 0.747289" mass="1.01738" diaginertia="0.0063132 0.006055 0.000954799"/>
                <joint name="ankle_roll_r_joint" pos="0 0 0" axis="1 0 0" range="-0.4363 0.4363" actuatorfrcrange="-30 30"/>
                <geom type="mesh" class="visual" rgba="0.752941 0.752941 0.752941 1" mesh="ankle_roll_r_link"/>
              </body>
            </body>
          </body>
        </body>
      </body>
    </body>
    <body name="waist_yaw_link" pos="0 0 0">
      <inertial pos="-0.000661771 0.00055888 0.230886" quat="0.999938 -0.000532442 -0.0107028 -0.00306086" mass="22.6452" diaginertia="0.433075 0.38441 0.178937"/>
      <joint name="waist_yaw_joint" pos="0 0 0" axis="0 0 1" range="-2.96 3.14" actuatorfrcrange="-120 120"/>
      <geom type="mesh" class="visual" rgba="0.752941 0.752941 0.752941 1" mesh="waist_yaw_link"/>
      <geom pos="0.06958 0 0.035588" quat="0.95882 0 0.284016 0" type="mesh" rgba="0.752941 0.752941 0.752941 1" mesh="camera_body_front_link"/>
      <geom pos="-0.1054 0 0.29423" quat="0.216438 2.79111e-06 0.976296 2.79111e-06" type="mesh" rgba="0.752941 0.752941 0.752941 1" mesh="camera_body_back_link"/>
      <body name="head_yaw_link" pos="-0.002 0 0.56508">
        <inertial pos="-0.000198116 0.000454283 0.00724628" quat="0.57671 0.539615 -0.401775 0.463463" mass="0.0883927" diaginertia="0.000107085 9.42377e-05 7.56772e-05"/>
        <joint name="head_yaw_joint" pos="0 0 0" axis="0 0 1" range="-1.57 1.57" actuatorfrcrange="-9 9"/>
        <geom type="mesh" class="visual" rgba="0.752941 0.752941 0.752941 1" mesh="head_yaw_link"/>
        <body name="head_pitch_link" pos="0.01455 0 0.0304" quat="0.991445 0 0.130526 0">
          <inertial pos="-0.000274 0.004118 2.3e-05" quat="0.573495 0.563096 -0.428362 0.412957" mass="0.23046" diaginertia="9.53059e-05 9.17204e-05 5.39736e-05"/>
          <joint name="head_pitch_joint" pos="0 0 0" axis="0 1 0" range="-0.43 0.43" actuatorfrcrange="-9 9"/>
          <geom type="mesh" class="visual" rgba="0.752941 0.752941 0.752941 1" mesh="head_pitch_link"/>
          <body name="head_roll_link" pos="0 0 0">
            <inertial pos="0.0264895 0.00110774 0.056513" quat="0.584383 0.360484 0.348297 0.638151" mass="0.944627" diaginertia="0.00356421 0.003377 0.00217881"/>
            <joint name="head_roll_joint" pos="0 0 0" axis="1 0 0" range="-0.43 0.43" actuatorfrcrange="-9 9"/>
            <geom type="mesh" class="visual" rgba="0.752941 0.752941 0.752941 1" mesh="head_roll_link"/>
            <geom pos="0.052782 -6.5455e-05 0.067499" quat="0.991445 0 0.130526 0" type="mesh" class="visual" rgba="0.752941 0.752941 0.752941 1" mesh="camera_head_link"/>
          </body>
        </body>
      </body>
      <body name="shoulder_pitch_l_link" pos="0 0.14539 0.37721" quat="0.999048 0.0436192 0 0">
        <inertial pos="0.00754 0.064361 -3.7e-05" quat="0.401219 0.582335 -0.401019 0.582317" mass="1.03063" diaginertia="0.000636 0.000545537 0.000470463"/>
        <joint name="shoulder_pitch_l_joint" pos="0 0 0" axis="0 1 0" range="-2.96 2.96" actuatorfrcrange="-91 91"/>
        <geom type="mesh" class="visual" rgba="0.752941 0.752941 0.752941 1" mesh="shoulder_pitch_l_link"/>
        <body name="shoulder_roll_l_link" pos="0 0.068 0">
          <inertial pos="0.00106653 0.00220629 -0.0441161" quat="0.7082 -0.00329147 -0.0128765 0.705886" mass="0.412601" diaginertia="0.00126407 0.000939019 0.000895909"/>
          <joint name="shoulder_roll_l_joint" pos="0 0 0" axis="1 0 0" range="-0.2618 3.4" actuatorfrcrange="-60 60"/>
          <geom type="mesh" class="visual" rgba="0.752941 0.752941 0.752941 1" mesh="shoulder_roll_l_link"/>
          <body name="shoulder_yaw_l_link" pos="0 0 -0.1025">
            <inertial pos="0.008387 0.00373 -0.11229" quat="0.95062 -0.00536915 0.0606486 0.304326" mass="1.3076" diaginertia="0.00944038 0.00923249 0.000707129"/>
            <joint name="shoulder_yaw_l_joint" pos="0 0 0" axis="0 0 1" range="-2.96 2.96" actuatorfrcrange="-30 30"/>
            <geom type="mesh" class="visual" rgba="0.752941 0.752941 0.752941 1" mesh="shoulder_yaw_l_link"/>
            <body name="elbow_pitch_l_link" pos="0.02 0 -0.1975">
              <inertial pos="-0.014369 -9e-05 -0.024267" quat="0.501992 0.622759 -0.464622 0.379872" mass="0.222661" diaginertia="0.000398305 0.000361097 0.000199597"/>
              <joint name="elbow_pitch_l_joint" pos="0 0 0" axis="0 1 0" range="-2.61 0.261" actuatorfrcrange="-30 30"/>
              <geom type="mesh" class="visual" rgba="0.752941 0.752941 0.752941 1" mesh="elbow_pitch_l_link"/>
              <body name="elbow_yaw_l_link" pos="-0.02 0 -0.0543">
                <inertial pos="8e-05 0.00115 -0.069083" quat="0.999899 -0.012607 0.000668448 0.00659261" mass="0.990079" diaginertia="0.00296102 0.00287955 0.000420432"/>
                <joint name="elbow_yaw_l_joint" pos="0 0 0" axis="0 0 1" range="-2.9671 2.9671" actuatorfrcrange="-15 15"/>
                <geom type="mesh" class="visual" rgba="0.752941 0.752941 0.752941 1" mesh="elbow_yaw_l_link"/>
                <body name="wrist_pitch_l_link" pos="0 0.002 -0.1887">
                  <inertial pos="0.005341 0.000652 -0.018511" quat="0.314863 0.66524 0.28303 0.614988" mass="0.266415" diaginertia="0.000116841 0.000110463 7.36959e-05"/>
                  <joint name="wrist_pitch_l_joint" pos="0 0 0" axis="0 1 0" range="-1.3 1.65" actuatorfrcrange="-9 9"/>
                  <geom type="mesh" class="visual" rgba="0.752941 0.752941 0.752941 1" mesh="wrist_pitch_l_link"/>
                  <body name="wrist_roll_l_link" pos="5.0485e-05 0 -0.02">
                    <inertial pos="0.001596 0.000155 -0.018822" quat="0.497592 0.500808 0.515059 0.486114" mass="0.065684" diaginertia="7.30062e-05 6.40263e-05 3.29676e-05"/>
                    <joint name="wrist_roll_l_joint" pos="0 0 0" axis="1 0 0" range="-1.04 0.785" actuatorfrcrange="-9 9"/>
                    <geom type="mesh" class="visual" rgba="0.752941 0.752941 0.752941 1" mesh="wrist_roll_l_link"/>
                  </body>
                </body>
              </body>
            </body>
          </body>
        </body>
      </body>
      <body name="shoulder_pitch_r_link" pos="0 -0.14539 0.37721" quat="0.999048 -0.0436192 0 0">
        <inertial pos="0.00754 -0.064361 -3.7e-05" quat="0.582335 0.401219 -0.582317 0.401019" mass="1.03063" diaginertia="0.000636 0.000545537 0.000470463"/>
        <joint name="shoulder_pitch_r_joint" pos="0 0 0" axis="0 1 0" range="-2.96 2.96" actuatorfrcrange="-91 91"/>
        <geom type="mesh" class="visual" rgba="0.752941 0.752941 0.752941 1" mesh="shoulder_pitch_r_link"/>
        <body name="shoulder_roll_r_link" pos="0 -0.068 0">
          <inertial pos="0.00106653 -0.00220629 -0.0441161" quat="0.705886 -0.0128765 -0.00329147 0.7082" mass="0.412601" diaginertia="0.00126407 0.000939019 0.000895909"/>
          <joint name="shoulder_roll_r_joint" pos="0 0 0" axis="1 0 0" range="-3.4 0.2618" actuatorfrcrange="-60 60"/>
          <geom type="mesh" class="visual" rgba="0.752941 0.752941 0.752941 1" mesh="shoulder_roll_r_link"/>
          <body name="shoulder_yaw_r_link" pos="0 0 -0.1025">
            <inertial pos="0.008387 -0.00373 -0.11229" quat="0.95062 0.00536915 0.0606486 -0.304326" mass="1.3076" diaginertia="0.00944038 0.00923249 0.000707129"/>
            <joint name="shoulder_yaw_r_joint" pos="0 0 0" axis="0 0 1" range="-2.96 2.96" actuatorfrcrange="-30 30"/>
            <geom type="mesh" class="visual" rgba="0.752941 0.752941 0.752941 1" mesh="shoulder_yaw_r_link"/>
            <body name="elbow_pitch_r_link" pos="0.02 0 -0.1975">
              <inertial pos="-0.014369 9e-05 -0.024267" quat="0.622759 0.501992 -0.379872 0.464622" mass="0.222661" diaginertia="0.000398305 0.000361097 0.000199597"/>
              <joint name="elbow_pitch_r_joint" pos="0 0 0" axis="0 1 0" range="-2.61 0.261" actuatorfrcrange="-30 30"/>
              <geom type="mesh" class="visual" rgba="0.752941 0.752941 0.752941 1" mesh="elbow_pitch_r_link"/>
              <body name="elbow_yaw_r_link" pos="-0.02 0 -0.0543">
                <inertial pos="8e-05 0.00115 -0.069083" quat="0.999899 -0.012607 0.000668448 0.00659261" mass="0.990079" diaginertia="0.00296102 0.00287955 0.000420432"/>
                <joint name="elbow_yaw_r_joint" pos="0 0 0" axis="0 0 1" range="-2.9671 2.9671" actuatorfrcrange="-15 15"/>
                <geom type="mesh" class="visual" rgba="0.752941 0.752941 0.752941 1" mesh="elbow_yaw_r_link"/>
                <body name="wrist_pitch_r_link" pos="0 -0.002 -0.1887">
                  <inertial pos="0.005341 -0.000652 -0.018511" quat="0.614988 0.28303 0.66524 0.314863" mass="0.266415" diaginertia="0.000116841 0.000110463 7.36959e-05"/>
                  <joint name="wrist_pitch_r_joint" pos="0 0 0" axis="0 1 0" range="-1.3 1.65" actuatorfrcrange="-9 9"/>
                  <geom type="mesh" class="visual" rgba="0.752941 0.752941 0.752941 1" mesh="wrist_pitch_r_link"/>
                  <body name="wrist_roll_r_link" pos="5.0485e-05 0 -0.02">
                    <inertial pos="0.001596 -0.000155 -0.018822" quat="0.486114 0.515059 0.500808 0.497592" mass="0.065684" diaginertia="7.30062e-05 6.40263e-05 3.29676e-05"/>
                    <joint name="wrist_roll_r_joint" pos="0 0 0" axis="1 0 0" range="-1.04 0.785" actuatorfrcrange="-9 9"/>
                    <geom type="mesh" class="visual" rgba="0.752941 0.752941 0.752941 1" mesh="wrist_roll_r_link"/>
                  </body>
                </body>
              </body>
            </body>
          </body>
       </body>
      </body>
    </body>
  </body>
  </worldbody>
  <actuator>
      <motor name="hip_roll_l"  joint="hip_roll_l_joint"  gear="1" ctrllimited="true" ctrlrange="-160 160"/>
      <motor name="hip_pitch_l" joint="hip_pitch_l_joint" gear="1" ctrllimited="true" ctrlrange="-300 300"/>
      <motor name="hip_yaw_l"   joint="hip_yaw_l_joint"   gear="1" ctrllimited="true" ctrlrange="-160 160"/>
      <motor name="knee_pitch_l" joint="knee_pitch_l_joint" gear="1" ctrllimited="true" ctrlrange="-300 300"/>
      <motor name="ankle_pitch_l" joint="ankle_pitch_l_joint" gear="1" ctrllimited="true" ctrlrange="-60 60"/>
      <motor name="ankle_roll_l"  joint="ankle_roll_l_joint"  gear="1" ctrllimited="true" ctrlrange="-30 30"/>
      <motor name="hip_roll_r"  joint="hip_roll_r_joint"  gear="1" ctrllimited="true" ctrlrange="-160 160"/>
      <motor name="hip_pitch_r" joint="hip_pitch_r_joint" gear="1" ctrllimited="true" ctrlrange="-300 300"/>
      <motor name="hip_yaw_r"   joint="hip_yaw_r_joint"   gear="1" ctrllimited="true" ctrlrange="-160 160"/>
      <motor name="knee_pitch_r" joint="knee_pitch_r_joint" gear="1" ctrllimited="true" ctrlrange="-300 300"/>
      <motor name="ankle_pitch_r" joint="ankle_pitch_r_joint" gear="1" ctrllimited="true" ctrlrange="-60 60"/>
      <motor name="ankle_roll_r"  joint="ankle_roll_r_joint"  gear="1" ctrllimited="true" ctrlrange="-30 30"/>
      <motor name="waist_yaw" joint="waist_yaw_joint" gear="1" ctrllimited="true" ctrlrange="-120 120"/>
      <motor name="head_yaw"   joint="head_yaw_joint"   gear="1" ctrllimited="true" ctrlrange="-9 9"/>
      <motor name="head_pitch" joint="head_pitch_joint" gear="1" ctrllimited="true" ctrlrange="-9 9"/>
      <motor name="head_roll"  joint="head_roll_joint"  gear="1" ctrllimited="true" ctrlrange="-9 9"/>
      <motor name="shoulder_pitch_l" joint="shoulder_pitch_l_joint" gear="1" ctrllimited="true" ctrlrange="-91 91"/>
      <motor name="shoulder_roll_l"  joint="shoulder_roll_l_joint"  gear="1" ctrllimited="true" ctrlrange="-60 60"/>
      <motor name="shoulder_yaw_l"   joint="shoulder_yaw_l_joint"   gear="1" ctrllimited="true" ctrlrange="-30 30"/>
      <motor name="elbow_pitch_l"    joint="elbow_pitch_l_joint"    gear="1" ctrllimited="true" ctrlrange="-30 30"/>
      <motor name="elbow_yaw_l"      joint="elbow_yaw_l_joint"      gear="1" ctrllimited="true" ctrlrange="-15 15"/>
      <motor name="wrist_pitch_l"    joint="wrist_pitch_l_joint"    gear="1" ctrllimited="true" ctrlrange="-9 9"/>
      <motor name="wrist_roll_l"     joint="wrist_roll_l_joint"     gear="1" ctrllimited="true" ctrlrange="-9 9"/>
      <motor name="shoulder_pitch_r" joint="shoulder_pitch_r_joint" gear="1" ctrllimited="true" ctrlrange="-91 91"/>
      <motor name="shoulder_roll_r"  joint="shoulder_roll_r_joint"  gear="1" ctrllimited="true" ctrlrange="-60 60"/>
      <motor name="shoulder_yaw_r"   joint="shoulder_yaw_r_joint"   gear="1" ctrllimited="true" ctrlrange="-30 30"/>
      <motor name="elbow_pitch_r"    joint="elbow_pitch_r_joint"    gear="1" ctrllimited="true" ctrlrange="-30 30"/>
      <motor name="elbow_yaw_r"      joint="elbow_yaw_r_joint"      gear="1" ctrllimited="true" ctrlrange="-15 15"/>
      <motor name="wrist_pitch_r"    joint="wrist_pitch_r_joint"    gear="1" ctrllimited="true" ctrlrange="-9 9"/>
      <motor name="wrist_roll_r"     joint="wrist_roll_r_joint"     gear="1" ctrllimited="true" ctrlrange="-9 9"/>
  </actuator>
  <sensor>
    <accelerometer name="imu_acc" site="imu_site"/>
    <gyro name="imu_gyro" site="imu_site"/>
    <framequat name="imu_quat" objtype="site" objname="imu_site"/>
  </sensor>
</mujoco>
